Workbook

Sheet 0_ReadMe
A1: NOVA ELECTRONICS — Cost-Resilience Sourcing Network: ILP + Monte Carlo Simulation Model
A2: Built from the uploaded case PDF (Exhibits 1-7) and cross-checked against the accompanying MBA report; all exhibit data matched exactly. Every colored (blue) cell is a hardcoded case input; every black cell is a live formula.
B4: Sheet | C4: What it contains | D4: Type | E4: Key output
B5: Inputs | C5: Exhibits 1-7 + policy parameters from the case PDF (source data) | D5: Data | E5: —
B6: ILP_A_CostFocused | C6: Cost-minimizing LP/ILP allocation, 60% concentration cap, S1-S4 qualified | D6: ILP | E6: Total landed cost
B7: ILP_B_Moderate | C7: Dual-sourcing LP/ILP, 50% concentration cap, S1,S2,S4,S5 qualified | D7: ILP | E7: Total landed cost
B8: ILP_C_HighResilience | C8: High-resilience LP/ILP, 40% concentration cap, all 5 suppliers qualified | D8: ILP | E8: Total landed cost
B9: Strategy_Comparison | C9: Side-by-side A/B/C normal-cost and simulated-resilience metrics | D9: Summary | E9: Resilience premium
B10: Sim_A_CostFocused | C10: 150-trial Monte Carlo for Strategy A (disruption, demand, yield, shock) | D10: Simulation | E10: Shortage probability
B11: Sim_B_Moderate | C11: 150-trial Monte Carlo for Strategy B | D11: Simulation | E11: Shortage probability
B12: Sim_C_HighResilience | C12: 150-trial Monte Carlo for Strategy C | D12: Simulation | E12: Shortage probability
A14: How to use
A15: 1. Change any blue cell on Inputs to re-run the whole model (disruption prob., demand, spot price, concentration cap, etc.).
A16: 2. On each ILP sheet, x[s,p] allocation and y_s qualification cells (blue) are Solver changing cells: open Data > Solver, set the objective cell (Total Landed Cost) to Min, and add the capacity / qualification-link / concentration / balance constraints shown on the sheet, to re-optimize.
A17: 3. Each Sim_ sheet recalculates a fresh 150-trial Monte Carlo every time the workbook recalculates (press F9). The live summary block (rows 5-6) updates automatically.
A18: 4. Strategy_Comparison pulls the normal-condition ILP costs and the live simulation results side by side.
A19: 5. A documented reconciliation note on Strategy_Comparison explains a small (approx Rs 5 lakh) rounding difference between this workbook formula-driven landed cost and the reports headline figure -- the underlying case data are identical; only the reports summary arithmetic differs slightly.

Sheet Inputs
A1: NOVA ELECTRONICS — CASE INPUT DATA (source: uploaded case PDF, Exhibits 1–7)
A2: All blue cells below are hardcoded inputs copied verbatim from the case PDF. Cross-checked against the accompanying MBA report (docx) — identical. Change these cells to run new scenarios; every formula elsewhere in this workbook flows from here.
A4: Exhibit 1 — Plant Requirements
A5: Plant | B5: Monthly Requirement (units) | C5: Shortage Loss / Unit (₹) | D5: Criticality
A6: P1 Pune | B6: 18000 | C6: 1800 | D6: High
A7: P2 Chennai | B7: 15000 | C7: 1800 | D7: Medium
A8: P3 Noida | B8: 12000 | C8: 2050 | D8: High
A10: Exhibit 2 — Supplier Economics and Risk
A11: Supplier | B11: Capacity (units/mo) | C11: Purchase Cost/Unit (₹) | D11: Qualification Cost/Month (₹) | E11: Disruption Probability
A12: S1 Alpha | B12: 16000 | C12: 1020 | D12: 250000 | E12: 0.06
A13: S2 Beta | B13: 14000 | C13: 980 | D13: 300000 | E13: 0.12
A14: S3 Gamma | B14: 13000 | C14: 1050 | D14: 200000 | E14: 0.04
A15: S4 Delta | B15: 12000 | C15: 950 | D15: 280000 | E15: 0.18
A16: S5 Epsilon | B16: 15000 | C16: 1090 | D16: 180000 | E16: 0.03
A18: Exhibit 3 — Freight Cost per Unit (₹)
A19: Supplier | B19: Pune | C19: Chennai | D19: Noida
A20: S1 Alpha | B20: 45 | C20: 70 | D20: 60
A21: S2 Beta | B21: 55 | C21: 40 | D21: 85
A22: S3 Gamma | B22: 70 | C22: 50 | D22: 75
A23: S4 Delta | B23: 35 | C23: 65 | D23: 90
A24: S5 Epsilon | B24: 80 | C24: 75 | D24: 40
A26: Exhibit 4 — Supplier Operating Characteristics
A27: Supplier | B27: Good-Quality Yield | C27: Normal Lead Time (days) | D27: Emergency Recovery (after 1 wk)
A28: S1 Alpha | B28: 0.988 | C28: 5 | D28: 0.6
A29: S2 Beta | B29: 0.992 | C29: 7 | D29: 0.5
A30: S3 Gamma | B30: 0.995 | C30: 6 | D30: 0.7
A31: S4 Delta | B31: 0.985 | C31: 4 | D31: 0.4
A32: S5 Epsilon | B32: 0.994 | C32: 8 | D32: 0.75
A34: Exhibit 5 — Emergency Market
A35: Emergency spot price / unit (₹) | B35: 1550
A36: Emergency market cap (units/month) | B36: 8000
A38: Exhibit 6 — Demand Condition
A39: Condition | B39: Probability | C39: Cumulative Prob. | D39: Demand Multiplier
A40: Weak | B40: 0.2 | C40: =SUM($B$40:B40) -> 0.2 | D40: 0.9
A41: Normal | B41: 0.55 | C41: =SUM($B$40:B41) -> 0.75 | D41: 1
A42: Strong | B42: 0.25 | C42: =SUM($B$40:B42) -> 1 | D42: 1.15
A44: Exhibit 7 — Disruption Severity if a Supplier Fails
A45: Severity | B45: Conditional Probability | C45: Cumulative Prob. | D45: Capacity Available
A46: Minor | B46: 0.35 | C46: =SUM($B$46:B46) -> 0.35 | D46: 0.6
A47: Major | B47: 0.45 | C47: =SUM($B$46:B47) -> 0.8 | D47: 0.3
...

Sheet ILP_A_CostFocused
A1: Strategy A — Cost-Focused (min. landed cost, 60% concentration cap)
A2: Decision variables x[s,p] (blue) are the Solver changing cells — pre-loaded with the optimal solution. y_s (blue, 1/0) marks qualified suppliers. Set up Excel Solver: Objective = Total Landed Cost cell (below); Changing cells = x[s,p] range; Constraints = capacity, qualification link, concentration, plant balance rows shown below; Solver engine = Simplex LP (or Evolutionary if y_s is left variable).
A4: Max concentration per plant (policy lever): | D4: 0.6
A5: Qualification-cost ceiling check (₹/month, policy pref.): | D5: =Inputs!$B$60 -> 4
A7: Decision Variables — x[s,p] Good Units Allocated (Solver Changing Cells)
A8: Supplier | B8: Qualified y_s (0/1) | C8: Pune x_s,P1 | D8: Chennai x_s,P2 | E8: Noida x_s,P3 | F8: Total Allocated | G8: Capacity | H8: Capacity Slack | I8: Qual. Link OK?
A9: S1 Alpha | B9: 1 | C9: 7112 | D9: 0 | E9: 7200 | F9: =SUM(C9:E9) -> 14312 | G9: =Inputs!$B$12 -> 16000 | H9: =G9-F9 -> 1688 | I9: =IF(F9<=G9*B9,"OK","VIOLATION") -> OK
A10: S2 Beta | B10: 1 | C10: 88 | D10: 9000 | E10: 4800 | F10: =SUM(C10:E10) -> 13888 | G10: =Inputs!$B$13 -> 14000 | H10: =G10-F10 -> 112 | I10: =IF(F10<=G10*B10,"OK","VIOLATION") -> OK
A11: S3 Gamma | B11: 1 | C11: 0 | D11: 4980 | E11: 0 | F11: =SUM(C11:E11) -> 4980 | G11: =Inputs!$B$14 -> 13000 | H11: =G11-F11 -> 8020 | I11: =IF(F11<=G11*B11,"OK","VIOLATION") -> OK
A12: S4 Delta | B12: 1 | C12: 10800 | D12: 1020 | E12: 0 | F12: =SUM(C12:E12) -> 11820 | G12: =Inputs!$B$15 -> 12000 | H12: =G12-F12 -> 180 | I12: =IF(F12<=G12*B12,"OK","VIOLATION") -> OK
A13: S5 Epsilon | B13: 0 | C13: 0 | D13: 0 | E13: 0 | F13: =SUM(C13:E13) -> 0 | G13: =Inputs!$B$16 -> 15000 | H13: =G13-F13 -> 15000 | I13: =IF(F13<=G13*B13,"OK","VIOLATION") -> OK
A14: TOTAL | B14: =SUM(B9:B13) -> 4 | C14: =SUM(C9:C13) -> 18000 | D14: =SUM(D9:D13) -> 15000 | E14: =SUM(E9:E13) -> 12000 | F14: =SUM(F9:F13) -> 45000 | G14: =SUM(G9:G13) -> 70000 | H14: =SUM(H9:H13) -> 25000
A16: Plant Balance — Supply + Emergency + Shortage = Demand
A17: Plant | B17: Demand (units) | C17: Good Supply (Σ x_s,p) | D17: Emergency u_p | E17: Unresolved Shortage z_p | F17: Total Covered | G17: Balance Check | H17: Shortage Loss ₹/unit
A18: P1 Pune | B18: =Inputs!$B$6 -> 18000 | C18: =SUM(C9:C13) -> 18000 | D18: 0 | E18: =MAX(0,B18-C18-D18) -> 0 | F18: =C18+D18+E18 -> 18000 | G18: =IF(F18=B18,"OK","CHECK") -> OK | H18: =Inputs!$C$6 -> 1800
A19: P2 Chennai | B19: =Inputs!$B$7 -> 15000 | C19: =SUM(D9:D13) -> 15000 | D19: 0 | E19: =MAX(0,B19-C19-D19) -> 0 | F19: =C19+D19+E19 -> 15000 | G19: =IF(F19=B19,"OK","CHECK") -> OK | H19: =Inputs!$C$7 -> 1800
A20: P3 Noida | B20: =Inputs!$B$8 -> 12000 | C20: =SUM(E9:E13) -> 12000 | D20: 0 | E20: =MAX(0,B20-C20-D20) -> 0 | F20: =C20+D20+E20 -> 12000 | G20: =IF(F20=B20,"OK","CHECK") -> OK | H20: =Inputs!$C$8 -> 2050
A22: Concentration Check — x[s,p] / Plant Demand ≤ Max Concentration
A23: Supplier | B23: Pune Share | C23: Chennai Share | D23: Noida Share | E23: Max Allowed | F23: Status Pune | G23: Status Chennai | H23: Status Noida
A24: S1 Alpha | B24: =C9/$B$18 -> 0.39511111 | C24: =D9/$B$19 -> 0 | D24: =E9/$B$20 -> 0.6 | E24: =$D$4 -> 0.6 | F24: =IF(B24<=$E$24+0.0001,"OK","OVER") -> OK | G24: =IF(C24<=$E$24+0.0001,"OK","OVER") -> OK | H24: =IF(D24<=$E$24+0.0001,"OK","OVER") -> OK
A25: S2 Beta | B25: =C10/$B$18 -> 0.0048888889 | C25: =D10/$B$19 -> 0.6 | D25: =E10/$B$20 -> 0.4 | E25: =$D$4 -> 0.6 | F25: =IF(B25<=$E$25+0.0001,"OK","OVER") -> OK | G25: =IF(C25<=$E$25+0.0001,"OK","OVER") -> OK | H25: =IF(D25<=$E$25+0.0001,"OK","OVER") -> OK
A26: S3 Gamma | B26: =C11/$B$18 -> 0 | C26: =D11/$B$19 -> 0.332 | D26: =E11/$B$20 -> 0 | E26: =$D$4 -> 0.6 | F26: =IF(B26<=$E$26+0.0001,"OK","OVER") -> OK | G26: =IF(C26<=$E$26+0.0001,"OK","OVER") -> OK | H26: =IF(D26<=$E$26+0.0001,"OK","OVER") -> OK
A27: S4 Delta | B27: =C12/$B$18 -> 0.6 | C27: =D12/$B$19 -> 0.068 | D27: =E12/$B$20 -> 0 | E27: =$D$4 -> 0.6 | F27: =IF(B27<=$E$27+0.0001,"OK","OVER") -> OK | G27: =IF(C27<=$E$27+0.0001,"OK","OVER") -> OK | H27: =IF(D27<=$E$27+0.0001,"OK","OVER") -> OK
A28: S5 Epsilon | B28: =C13/$B$18 -> 0 | C28: =D13/$B$19 -> 0 | D28: =E13/$B$20 -> 0 | E28: =$D$4 -> 0.6 | F28: =IF(B28<=$E$28+0.0001,"OK","OVER") -> OK | G28: =IF(C28<=$E$28+0.0001,"OK","OVER") -> OK | H28: =IF(D28<=$E$28+0.0001,"OK","OVER") -> OK
A30: High-Criticality Protection Check (P1 & P3 need ≥ 2 qualified, supplying suppliers)
A31: Suppliers actively supplying Pune (P1): | F31: =COUNTIF(C9:C13,">0") -> 3 | G31: =IF(F31>=2,"OK","RISK") -> OK
A32: Suppliers actively supplying Noida (P3): | F32: =COUNTIF(E9:E13,">0") -> 2 | G32: =IF(F32>=2,"OK","RISK") -> OK
A34: Objective Function — Total Landed Cost
A35: Supplier | B35: Pune Eff. Cost/Unit (Purch+Frt)/Yield | C35: Chennai Eff. Cost/Unit | D35: Noida Eff. Cost/Unit | E35: Pune Cost ₹ | F35: Chennai Cost ₹ | G35: Noida Cost ₹ | H35: Supplier Total ₹
A36: S1 Alpha | B36: =(Inputs!$C$12+Inputs!$B$20)/Inputs!$B$28 -> 1077.9352 | C36: =(Inputs!$C$12+Inputs!$C$20)/Inputs!$B$28 -> 1103.2389 | D36: =(Inputs!$C$12+Inputs!$D$20)/Inputs!$B$28 -> 1093.1174 | E36: =C9*B36 -> 7666275.3 | F36: =D9*C36 -> 0 | G36: =E9*D36 -> 7870445.3 | H36: =SUM(E36:G36) -> 15536721
A37: S2 Beta | B37: =(Inputs!$C$13+Inputs!$B$21)/Inputs!$B$29 -> 1043.3468 | C37: =(Inputs!$C$13+Inputs!$C$21)/Inputs!$B$29 -> 1028.2258 | D37: =(Inputs!$C$13+Inputs!$D$21)/Inputs!$B$29 -> 1073.5887 | E37: =C10*B37 -> 91814.516 | F37: =D10*C37 -> 9254032.3 | G37: =E10*D37 -> 5153225.8 | H37: =SUM(E37:G37) -> 14499073
A38: S3 Gamma | B38: =(Inputs!$C$14+Inputs!$B$22)/Inputs!$B$30 -> 1125.6281 | C38: =(Inputs!$C$14+Inputs!$C$22)/Inputs!$B$30 -> 1105.5276 | D38: =(Inputs!$C$14+Inputs!$D$22)/Inputs!$B$30 -> 1130.6533 | E38: =C11*B38 -> 0 | F38: =D11*C38 -> 5505527.6 | G38: =E11*D38 -> 0 | H38: =SUM(E38:G38) -> 5505527.6
A39: S4 Delta | B39: =(Inputs!$C$15+Inputs!$B$23)/Inputs!$B$31 -> 1000 | C39: =(Inputs!$C$15+Inputs!$C$23)/Inputs!$B$31 -> 1030.4569 | D39: =(Inputs!$C$15+Inputs!$D$23)/Inputs!$B$31 -> 1055.8376 | E39: =C12*B39 -> 10800000 | F39: =D12*C39 -> 1051066 | G39: =E12*D39 -> 0 | H39: =SUM(E39:G39) -> 11851066
A40: S5 Epsilon | B40: =(Inputs!$C$16+Inputs!$B$24)/Inputs!$B$32 -> 1177.0624 | C40: =(Inputs!$C$16+Inputs!$C$24)/Inputs!$B$32 -> 1172.0322 | D40: =(Inputs!$C$16+Inputs!$D$24)/Inputs!$B$32 -> 1136.8209 | E40: =C13*B40 -> 0 | F40: =D13*C40 -> 0 | G40: =E13*D40 -> 0 | H40: =SUM(E40:G40) -> 0
A41: TOTAL SOURCING COST | E41: =SUM(E36:E40) -> 18558090 | F41: =SUM(F36:F40) -> 15810626 | G41: =SUM(G36:G40) -> 13023671 | H41: =SUM(H36:H40) -> 47392387
A43: Emergency sourcing cost (Σ u_p × spot price): | F43: =SUM(D18:D20)*Inputs!$B$35 -> 0
A44: Unresolved shortage cost (Σ z_p × loss/unit): | F44: =SUMPRODUCT(E18:E20,H18:H20) -> 0
A45: Qualification cost (Σ y_s × QualCost_s): | F45: =SUMPRODUCT(B9:B13,Inputs!$D$12:$D$16) -> 1030000
A47: TOTAL LANDED COST / MONTH | F47: =H41+F43+F44+F45 -> 48422387
A49: Qualification cost vs. ceiling preference: | F49: =IF(F45<=Inputs!$B$60,"Within ₹9L preference","Exceeds ₹9L preference (see Sensitivity)") -> Exceeds ₹9L preference (see Sensitivity)
...

Sheet ILP_B_Moderate
A1: Strategy B — Moderate Resilience (dual-sourcing, 50% concentration cap)
A2: Decision variables x[s,p] (blue) are the Solver changing cells — pre-loaded with the optimal solution. y_s (blue, 1/0) marks qualified suppliers. Set up Excel Solver: Objective = Total Landed Cost cell (below); Changing cells = x[s,p] range; Constraints = capacity, qualification link, concentration, plant balance rows shown below; Solver engine = Simplex LP (or Evolutionary if y_s is left variable).
A4: Max concentration per plant (policy lever): | D4: 0.5
A5: Qualification-cost ceiling check (₹/month, policy pref.): | D5: =Inputs!$B$60 -> 4
A7: Decision Variables — x[s,p] Good Units Allocated (Solver Changing Cells)
A8: Supplier | B8: Qualified y_s (0/1) | C8: Pune x_s,P1 | D8: Chennai x_s,P2 | E8: Noida x_s,P3 | F8: Total Allocated | G8: Capacity | H8: Capacity Slack | I8: Qual. Link OK?
A9: S1 Alpha | B9: 1 | C9: 5128 | D9: 4680 | E9: 6000 | F9: =SUM(C9:E9) -> 15808 | G9: =Inputs!$B$12 -> 16000 | H9: =G9-F9 -> 192 | I9: =IF(F9<=G9*B9,"OK","VIOLATION") -> OK
A10: S2 Beta | B10: 1 | C10: 3872 | D10: 7500 | E10: 2516 | F10: =SUM(C10:E10) -> 13888 | G10: =Inputs!$B$13 -> 14000 | H10: =G10-F10 -> 112 | I10: =IF(F10<=G10*B10,"OK","VIOLATION") -> OK
A11: S3 Gamma | B11: 0 | C11: 0 | D11: 0 | E11: 0 | F11: =SUM(C11:E11) -> 0 | G11: =Inputs!$B$14 -> 13000 | H11: =G11-F11 -> 13000 | I11: =IF(F11<=G11*B11,"OK","VIOLATION") -> OK
A12: S4 Delta | B12: 1 | C12: 9000 | D12: 2820 | E12: 0 | F12: =SUM(C12:E12) -> 11820 | G12: =Inputs!$B$15 -> 12000 | H12: =G12-F12 -> 180 | I12: =IF(F12<=G12*B12,"OK","VIOLATION") -> OK
A13: S5 Epsilon | B13: 1 | C13: 0 | D13: 0 | E13: 3484 | F13: =SUM(C13:E13) -> 3484 | G13: =Inputs!$B$16 -> 15000 | H13: =G13-F13 -> 11516 | I13: =IF(F13<=G13*B13,"OK","VIOLATION") -> OK
A14: TOTAL | B14: =SUM(B9:B13) -> 4 | C14: =SUM(C9:C13) -> 18000 | D14: =SUM(D9:D13) -> 15000 | E14: =SUM(E9:E13) -> 12000 | F14: =SUM(F9:F13) -> 45000 | G14: =SUM(G9:G13) -> 70000 | H14: =SUM(H9:H13) -> 25000
A16: Plant Balance — Supply + Emergency + Shortage = Demand
A17: Plant | B17: Demand (units) | C17: Good Supply (Σ x_s,p) | D17: Emergency u_p | E17: Unresolved Shortage z_p | F17: Total Covered | G17: Balance Check | H17: Shortage Loss ₹/unit
A18: P1 Pune | B18: =Inputs!$B$6 -> 18000 | C18: =SUM(C9:C13) -> 18000 | D18: 0 | E18: =MAX(0,B18-C18-D18) -> 0 | F18: =C18+D18+E18 -> 18000 | G18: =IF(F18=B18,"OK","CHECK") -> OK | H18: =Inputs!$C$6 -> 1800
A19: P2 Chennai | B19: =Inputs!$B$7 -> 15000 | C19: =SUM(D9:D13) -> 15000 | D19: 0 | E19: =MAX(0,B19-C19-D19) -> 0 | F19: =C19+D19+E19 -> 15000 | G19: =IF(F19=B19,"OK","CHECK") -> OK | H19: =Inputs!$C$7 -> 1800
A20: P3 Noida | B20: =Inputs!$B$8 -> 12000 | C20: =SUM(E9:E13) -> 12000 | D20: 0 | E20: =MAX(0,B20-C20-D20) -> 0 | F20: =C20+D20+E20 -> 12000 | G20: =IF(F20=B20,"OK","CHECK") -> OK | H20: =Inputs!$C$8 -> 2050
A22: Concentration Check — x[s,p] / Plant Demand ≤ Max Concentration
A23: Supplier | B23: Pune Share | C23: Chennai Share | D23: Noida Share | E23: Max Allowed | F23: Status Pune | G23: Status Chennai | H23: Status Noida
A24: S1 Alpha | B24: =C9/$B$18 -> 0.28488889 | C24: =D9/$B$19 -> 0.312 | D24: =E9/$B$20 -> 0.5 | E24: =$D$4 -> 0.5 | F24: =IF(B24<=$E$24+0.0001,"OK","OVER") -> OK | G24: =IF(C24<=$E$24+0.0001,"OK","OVER") -> OK | H24: =IF(D24<=$E$24+0.0001,"OK","OVER") -> OK
A25: S2 Beta | B25: =C10/$B$18 -> 0.21511111 | C25: =D10/$B$19 -> 0.5 | D25: =E10/$B$20 -> 0.20966667 | E25: =$D$4 -> 0.5 | F25: =IF(B25<=$E$25+0.0001,"OK","OVER") -> OK | G25: =IF(C25<=$E$25+0.0001,"OK","OVER") -> OK | H25: =IF(D25<=$E$25+0.0001,"OK","OVER") -> OK
A26: S3 Gamma | B26: =C11/$B$18 -> 0 | C26: =D11/$B$19 -> 0 | D26: =E11/$B$20 -> 0 | E26: =$D$4 -> 0.5 | F26: =IF(B26<=$E$26+0.0001,"OK","OVER") -> OK | G26: =IF(C26<=$E$26+0.0001,"OK","OVER") -> OK | H26: =IF(D26<=$E$26+0.0001,"OK","OVER") -> OK
A27: S4 Delta | B27: =C12/$B$18 -> 0.5 | C27: =D12/$B$19 -> 0.188 | D27: =E12/$B$20 -> 0 | E27: =$D$4 -> 0.5 | F27: =IF(B27<=$E$27+0.0001,"OK","OVER") -> OK | G27: =IF(C27<=$E$27+0.0001,"OK","OVER") -> OK | H27: =IF(D27<=$E$27+0.0001,"OK","OVER") -> OK
A28: S5 Epsilon | B28: =C13/$B$18 -> 0 | C28: =D13/$B$19 -> 0 | D28: =E13/$B$20 -> 0.29033333 | E28: =$D$4 -> 0.5 | F28: =IF(B28<=$E$28+0.0001,"OK","OVER") -> OK | G28: =IF(C28<=$E$28+0.0001,"OK","OVER") -> OK | H28: =IF(D28<=$E$28+0.0001,"OK","OVER") -> OK
A30: High-Criticality Protection Check (P1 & P3 need ≥ 2 qualified, supplying suppliers)
A31: Suppliers actively supplying Pune (P1): | F31: =COUNTIF(C9:C13,">0") -> 3 | G31: =IF(F31>=2,"OK","RISK") -> OK
A32: Suppliers actively supplying Noida (P3): | F32: =COUNTIF(E9:E13,">0") -> 3 | G32: =IF(F32>=2,"OK","RISK") -> OK
A34: Objective Function — Total Landed Cost
A35: Supplier | B35: Pune Eff. Cost/Unit (Purch+Frt)/Yield | C35: Chennai Eff. Cost/Unit | D35: Noida Eff. Cost/Unit | E35: Pune Cost ₹ | F35: Chennai Cost ₹ | G35: Noida Cost ₹ | H35: Supplier Total ₹
A36: S1 Alpha | B36: =(Inputs!$C$12+Inputs!$B$20)/Inputs!$B$28 -> 1077.9352 | C36: =(Inputs!$C$12+Inputs!$C$20)/Inputs!$B$28 -> 1103.2389 | D36: =(Inputs!$C$12+Inputs!$D$20)/Inputs!$B$28 -> 1093.1174 | E36: =C9*B36 -> 5527651.8 | F36: =D9*C36 -> 5163157.9 | G36: =E9*D36 -> 6558704.5 | H36: =SUM(E36:G36) -> 17249514
A37: S2 Beta | B37: =(Inputs!$C$13+Inputs!$B$21)/Inputs!$B$29 -> 1043.3468 | C37: =(Inputs!$C$13+Inputs!$C$21)/Inputs!$B$29 -> 1028.2258 | D37: =(Inputs!$C$13+Inputs!$D$21)/Inputs!$B$29 -> 1073.5887 | E37: =C10*B37 -> 4039838.7 | F37: =D10*C37 -> 7711693.5 | G37: =E10*D37 -> 2701149.2 | H37: =SUM(E37:G37) -> 14452681
A38: S3 Gamma | B38: =(Inputs!$C$14+Inputs!$B$22)/Inputs!$B$30 -> 1125.6281 | C38: =(Inputs!$C$14+Inputs!$C$22)/Inputs!$B$30 -> 1105.5276 | D38: =(Inputs!$C$14+Inputs!$D$22)/Inputs!$B$30 -> 1130.6533 | E38: =C11*B38 -> 0 | F38: =D11*C38 -> 0 | G38: =E11*D38 -> 0 | H38: =SUM(E38:G38) -> 0
A39: S4 Delta | B39: =(Inputs!$C$15+Inputs!$B$23)/Inputs!$B$31 -> 1000 | C39: =(Inputs!$C$15+Inputs!$C$23)/Inputs!$B$31 -> 1030.4569 | D39: =(Inputs!$C$15+Inputs!$D$23)/Inputs!$B$31 -> 1055.8376 | E39: =C12*B39 -> 9000000 | F39: =D12*C39 -> 2905888.3 | G39: =E12*D39 -> 0 | H39: =SUM(E39:G39) -> 11905888
A40: S5 Epsilon | B40: =(Inputs!$C$16+Inputs!$B$24)/Inputs!$B$32 -> 1177.0624 | C40: =(Inputs!$C$16+Inputs!$C$24)/Inputs!$B$32 -> 1172.0322 | D40: =(Inputs!$C$16+Inputs!$D$24)/Inputs!$B$32 -> 1136.8209 | E40: =C13*B40 -> 0 | F40: =D13*C40 -> 0 | G40: =E13*D40 -> 3960684.1 | H40: =SUM(E40:G40) -> 3960684.1
A41: TOTAL SOURCING COST | E41: =SUM(E36:E40) -> 18567491 | F41: =SUM(F36:F40) -> 15780740 | G41: =SUM(G36:G40) -> 13220538 | H41: =SUM(H36:H40) -> 47568768
A43: Emergency sourcing cost (Σ u_p × spot price): | F43: =SUM(D18:D20)*Inputs!$B$35 -> 0
A44: Unresolved shortage cost (Σ z_p × loss/unit): | F44: =SUMPRODUCT(E18:E20,H18:H20) -> 0
A45: Qualification cost (Σ y_s × QualCost_s): | F45: =SUMPRODUCT(B9:B13,Inputs!$D$12:$D$16) -> 1010000
A47: TOTAL LANDED COST / MONTH | F47: =H41+F43+F44+F45 -> 48578768
A49: Qualification cost vs. ceiling preference: | F49: =IF(F45<=Inputs!$B$60,"Within ₹9L preference","Exceeds ₹9L preference (see Sensitivity)") -> Exceeds ₹9L preference (see Sensitivity)
...

Sheet ILP_C_HighResilience
A1: Strategy C — High Resilience (all suppliers qualified, 40% concentration cap)
A2: Decision variables x[s,p] (blue) are the Solver changing cells — pre-loaded with the optimal solution. y_s (blue, 1/0) marks qualified suppliers. Set up Excel Solver: Objective = Total Landed Cost cell (below); Changing cells = x[s,p] range; Constraints = capacity, qualification link, concentration, plant balance rows shown below; Solver engine = Simplex LP (or Evolutionary if y_s is left variable).
A4: Max concentration per plant (policy lever): | D4: 0.4
A5: Qualification-cost ceiling check (₹/month, policy pref.): | D5: =Inputs!$B$60 -> 4
A7: Decision Variables — x[s,p] Good Units Allocated (Solver Changing Cells)
A8: Supplier | B8: Qualified y_s (0/1) | C8: Pune x_s,P1 | D8: Chennai x_s,P2 | E8: Noida x_s,P3 | F8: Total Allocated | G8: Capacity | H8: Capacity Slack | I8: Qual. Link OK?
A9: S1 Alpha | B9: 1 | C9: 7200 | D9: 0 | E9: 4800 | F9: =SUM(C9:E9) -> 12000 | G9: =Inputs!$B$12 -> 16000 | H9: =G9-F9 -> 4000 | I9: =IF(F9<=G9*B9,"OK","VIOLATION") -> OK
A10: S2 Beta | B10: 1 | C10: 3600 | D10: 6000 | E10: 4288 | F10: =SUM(C10:E10) -> 13888 | G10: =Inputs!$B$13 -> 14000 | H10: =G10-F10 -> 112 | I10: =IF(F10<=G10*B10,"OK","VIOLATION") -> OK
A11: S3 Gamma | B11: 1 | C11: 0 | D11: 4380 | E11: 2912 | F11: =SUM(C11:E11) -> 7292 | G11: =Inputs!$B$14 -> 13000 | H11: =G11-F11 -> 5708 | I11: =IF(F11<=G11*B11,"OK","VIOLATION") -> OK
A12: S4 Delta | B12: 1 | C12: 7200 | D12: 4620 | E12: 0 | F12: =SUM(C12:E12) -> 11820 | G12: =Inputs!$B$15 -> 12000 | H12: =G12-F12 -> 180 | I12: =IF(F12<=G12*B12,"OK","VIOLATION") -> OK
A13: S5 Epsilon | B13: 1 | C13: 0 | D13: 0 | E13: 0 | F13: =SUM(C13:E13) -> 0 | G13: =Inputs!$B$16 -> 15000 | H13: =G13-F13 -> 15000 | I13: =IF(F13<=G13*B13,"OK","VIOLATION") -> OK
A14: TOTAL | B14: =SUM(B9:B13) -> 5 | C14: =SUM(C9:C13) -> 18000 | D14: =SUM(D9:D13) -> 15000 | E14: =SUM(E9:E13) -> 12000 | F14: =SUM(F9:F13) -> 45000 | G14: =SUM(G9:G13) -> 70000 | H14: =SUM(H9:H13) -> 25000
A16: Plant Balance — Supply + Emergency + Shortage = Demand
A17: Plant | B17: Demand (units) | C17: Good Supply (Σ x_s,p) | D17: Emergency u_p | E17: Unresolved Shortage z_p | F17: Total Covered | G17: Balance Check | H17: Shortage Loss ₹/unit
A18: P1 Pune | B18: =Inputs!$B$6 -> 18000 | C18: =SUM(C9:C13) -> 18000 | D18: 0 | E18: =MAX(0,B18-C18-D18) -> 0 | F18: =C18+D18+E18 -> 18000 | G18: =IF(F18=B18,"OK","CHECK") -> OK | H18: =Inputs!$C$6 -> 1800
A19: P2 Chennai | B19: =Inputs!$B$7 -> 15000 | C19: =SUM(D9:D13) -> 15000 | D19: 0 | E19: =MAX(0,B19-C19-D19) -> 0 | F19: =C19+D19+E19 -> 15000 | G19: =IF(F19=B19,"OK","CHECK") -> OK | H19: =Inputs!$C$7 -> 1800
A20: P3 Noida | B20: =Inputs!$B$8 -> 12000 | C20: =SUM(E9:E13) -> 12000 | D20: 0 | E20: =MAX(0,B20-C20-D20) -> 0 | F20: =C20+D20+E20 -> 12000 | G20: =IF(F20=B20,"OK","CHECK") -> OK | H20: =Inputs!$C$8 -> 2050
A22: Concentration Check — x[s,p] / Plant Demand ≤ Max Concentration
A23: Supplier | B23: Pune Share | C23: Chennai Share | D23: Noida Share | E23: Max Allowed | F23: Status Pune | G23: Status Chennai | H23: Status Noida
A24: S1 Alpha | B24: =C9/$B$18 -> 0.4 | C24: =D9/$B$19 -> 0 | D24: =E9/$B$20 -> 0.4 | E24: =$D$4 -> 0.4 | F24: =IF(B24<=$E$24+0.0001,"OK","OVER") -> OK | G24: =IF(C24<=$E$24+0.0001,"OK","OVER") -> OK | H24: =IF(D24<=$E$24+0.0001,"OK","OVER") -> OK
A25: S2 Beta | B25: =C10/$B$18 -> 0.2 | C25: =D10/$B$19 -> 0.4 | D25: =E10/$B$20 -> 0.35733333 | E25: =$D$4 -> 0.4 | F25: =IF(B25<=$E$25+0.0001,"OK","OVER") -> OK | G25: =IF(C25<=$E$25+0.0001,"OK","OVER") -> OK | H25: =IF(D25<=$E$25+0.0001,"OK","OVER") -> OK
A26: S3 Gamma | B26: =C11/$B$18 -> 0 | C26: =D11/$B$19 -> 0.292 | D26: =E11/$B$20 -> 0.24266667 | E26: =$D$4 -> 0.4 | F26: =IF(B26<=$E$26+0.0001,"OK","OVER") -> OK | G26: =IF(C26<=$E$26+0.0001,"OK","OVER") -> OK | H26: =IF(D26<=$E$26+0.0001,"OK","OVER") -> OK
A27: S4 Delta | B27: =C12/$B$18 -> 0.4 | C27: =D12/$B$19 -> 0.308 | D27: =E12/$B$20 -> 0 | E27: =$D$4 -> 0.4 | F27: =IF(B27<=$E$27+0.0001,"OK","OVER") -> OK | G27: =IF(C27<=$E$27+0.0001,"OK","OVER") -> OK | H27: =IF(D27<=$E$27+0.0001,"OK","OVER") -> OK
A28: S5 Epsilon | B28: =C13/$B$18 -> 0 | C28: =D13/$B$19 -> 0 | D28: =E13/$B$20 -> 0 | E28: =$D$4 -> 0.4 | F28: =IF(B28<=$E$28+0.0001,"OK","OVER") -> OK | G28: =IF(C28<=$E$28+0.0001,"OK","OVER") -> OK | H28: =IF(D28<=$E$28+0.0001,"OK","OVER") -> OK
A30: High-Criticality Protection Check (P1 & P3 need ≥ 2 qualified, supplying suppliers)
A31: Suppliers actively supplying Pune (P1): | F31: =COUNTIF(C9:C13,">0") -> 3 | G31: =IF(F31>=2,"OK","RISK") -> OK
A32: Suppliers actively supplying Noida (P3): | F32: =COUNTIF(E9:E13,">0") -> 3 | G32: =IF(F32>=2,"OK","RISK") -> OK
A34: Objective Function — Total Landed Cost
A35: Supplier | B35: Pune Eff. Cost/Unit (Purch+Frt)/Yield | C35: Chennai Eff. Cost/Unit | D35: Noida Eff. Cost/Unit | E35: Pune Cost ₹ | F35: Chennai Cost ₹ | G35: Noida Cost ₹ | H35: Supplier Total ₹
A36: S1 Alpha | B36: =(Inputs!$C$12+Inputs!$B$20)/Inputs!$B$28 -> 1077.9352 | C36: =(Inputs!$C$12+Inputs!$C$20)/Inputs!$B$28 -> 1103.2389 | D36: =(Inputs!$C$12+Inputs!$D$20)/Inputs!$B$28 -> 1093.1174 | E36: =C9*B36 -> 7761133.6 | F36: =D9*C36 -> 0 | G36: =E9*D36 -> 5246963.6 | H36: =SUM(E36:G36) -> 13008097
A37: S2 Beta | B37: =(Inputs!$C$13+Inputs!$B$21)/Inputs!$B$29 -> 1043.3468 | C37: =(Inputs!$C$13+Inputs!$C$21)/Inputs!$B$29 -> 1028.2258 | D37: =(Inputs!$C$13+Inputs!$D$21)/Inputs!$B$29 -> 1073.5887 | E37: =C10*B37 -> 3756048.4 | F37: =D10*C37 -> 6169354.8 | G37: =E10*D37 -> 4603548.4 | H37: =SUM(E37:G37) -> 14528952
A38: S3 Gamma | B38: =(Inputs!$C$14+Inputs!$B$22)/Inputs!$B$30 -> 1125.6281 | C38: =(Inputs!$C$14+Inputs!$C$22)/Inputs!$B$30 -> 1105.5276 | D38: =(Inputs!$C$14+Inputs!$D$22)/Inputs!$B$30 -> 1130.6533 | E38: =C11*B38 -> 0 | F38: =D11*C38 -> 4842211.1 | G38: =E11*D38 -> 3292462.3 | H38: =SUM(E38:G38) -> 8134673.4
A39: S4 Delta | B39: =(Inputs!$C$15+Inputs!$B$23)/Inputs!$B$31 -> 1000 | C39: =(Inputs!$C$15+Inputs!$C$23)/Inputs!$B$31 -> 1030.4569 | D39: =(Inputs!$C$15+Inputs!$D$23)/Inputs!$B$31 -> 1055.8376 | E39: =C12*B39 -> 7200000 | F39: =D12*C39 -> 4760710.7 | G39: =E12*D39 -> 0 | H39: =SUM(E39:G39) -> 11960711
A40: S5 Epsilon | B40: =(Inputs!$C$16+Inputs!$B$24)/Inputs!$B$32 -> 1177.0624 | C40: =(Inputs!$C$16+Inputs!$C$24)/Inputs!$B$32 -> 1172.0322 | D40: =(Inputs!$C$16+Inputs!$D$24)/Inputs!$B$32 -> 1136.8209 | E40: =C13*B40 -> 0 | F40: =D13*C40 -> 0 | G40: =E13*D40 -> 0 | H40: =SUM(E40:G40) -> 0
A41: TOTAL SOURCING COST | E41: =SUM(E36:E40) -> 18717182 | F41: =SUM(F36:F40) -> 15772277 | G41: =SUM(G36:G40) -> 13142974 | H41: =SUM(H36:H40) -> 47632433
A43: Emergency sourcing cost (Σ u_p × spot price): | F43: =SUM(D18:D20)*Inputs!$B$35 -> 0
A44: Unresolved shortage cost (Σ z_p × loss/unit): | F44: =SUMPRODUCT(E18:E20,H18:H20) -> 0
A45: Qualification cost (Σ y_s × QualCost_s): | F45: =SUMPRODUCT(B9:B13,Inputs!$D$12:$D$16) -> 1210000
A47: TOTAL LANDED COST / MONTH | F47: =H41+F43+F44+F45 -> 48842433
A49: Qualification cost vs. ceiling preference: | F49: =IF(F45<=Inputs!$B$60,"Within ₹9L preference","Exceeds ₹9L preference (see Sensitivity)") -> Exceeds ₹9L preference (see Sensitivity)
...

Sheet Strategy_Comparison
A1: Strategy Comparison — A vs B vs C (normal-condition ILP results)
A3: Metric | B3: A — Cost-Focused | C3: B — Moderate Resilience | D3: C — High Resilience
A4: Qualified suppliers | B4: =ILP_A_CostFocused!F49 -> Exceeds ₹9L preference (see Sensitivity) | C4: =ILP_B_Moderate!F49 -> Exceeds ₹9L preference (see Sensitivity) | D4: =ILP_C_HighResilience!F49 -> Exceeds ₹9L preference (see Sensitivity)
A5: Max concentration per plant | B5: =ILP_A_CostFocused!D4 -> 0.6 | C5: =ILP_B_Moderate!D4 -> 0.5 | D5: =ILP_C_HighResilience!D4 -> 0.4
A6: Sourcing cost (₹/month) | B6: =ILP_A_CostFocused!H41 -> 47392387 | C6: =ILP_B_Moderate!H41 -> 47568768 | D6: =ILP_C_HighResilience!H41 -> 47632433
A7: Qualification cost (₹/month) | B7: =ILP_A_CostFocused!F45 -> 1030000 | C7: =ILP_B_Moderate!F45 -> 1010000 | D7: =ILP_C_HighResilience!F45 -> 1210000
A8: Total normal landed cost (₹/month) | B8: =ILP_A_CostFocused!F47 -> 48422387 | C8: =ILP_B_Moderate!F47 -> 48578768 | D8: =ILP_C_HighResilience!F47 -> 48842433
A10: Resilience premium vs. cheapest strategy (₹/month) | B10: =B8-MIN($B$8:$D$8) -> 0 | C10: =C8-MIN($B$8:$D$8) -> 156381.19 | D10: =D8-MIN($B$8:$D$8) -> 420045.95
A12: Simulation Results (link to Sim_Summary sheet — run after Monte Carlo sheets are built)
A13: Metric | B13: A — Cost-Focused | C13: B — Moderate Resilience | D13: C — High Resilience
A14: Network shortage probability | B14: =Sim_A_CostFocused!A6 -> 0 | C14: =Sim_B_Moderate!A6 -> 0 | D14: =Sim_C_HighResilience!A6 -> 0
A15: Expected emergency purchase (units/mo) | B15: =Sim_A_CostFocused!B6 -> 16.090779 | C15: =Sim_B_Moderate!B6 -> 28.293754 | D15: =Sim_C_HighResilience!B6 -> 0
A16: Expected unresolved shortage (units/mo) | B16: =Sim_A_CostFocused!C6 -> 0 | C16: =Sim_B_Moderate!C6 -> 0 | D16: =Sim_C_HighResilience!C6 -> 0
A17: Expected disruption cost (₹/mo) | B17: =Sim_A_CostFocused!G6 -> 24940.707 | C17: =Sim_B_Moderate!G6 -> 43855.318 | D17: =Sim_C_HighResilience!G6 -> 0
A18: P1 Pune meets demand (probability) | B18: =Sim_A_CostFocused!H6 -> 1 | C18: =Sim_B_Moderate!H6 -> 1 | D18: =Sim_C_HighResilience!H6 -> 1
A19: P2 Chennai meets demand (probability) | B19: =Sim_A_CostFocused!I6 -> 1 | C19: =Sim_B_Moderate!I6 -> 1 | D19: =Sim_C_HighResilience!I6 -> 1
A20: P3 Noida meets demand (probability) | B20: =Sim_A_CostFocused!J6 -> 1 | C20: =Sim_B_Moderate!J6 -> 1 | D20: =Sim_C_HighResilience!J6 -> 1
A22: Note: Total normal landed cost above is computed directly from case-stated purchase cost, freight (Exhibit 3), and good-quality yield (Exhibit 4) using Effective Cost = (Purchase + Freight) / Yield, exactly as specified in the accompanying report's methodology section. Cross-checking this build against the report's own headline figures (e.g. Strategy A ≈ ₹4.894 crore) shows the report's stated totals are internally about ₹5.1–5.3 lakh higher than what its own allocation table and methodology formula reproduce — an arithmetic rounding artifact in the report's summary, not a difference in the underlying case data (Exhibits 1–7 are identical across the PDF and the report). This workbook's figures are the audited, formula-traceable numbers.

Sheet Sim_A_CostFocused
A1: Monte Carlo Simulation — Strategy A — Cost-Focused (150 trials/refresh — press F9 to redraw)
A2: Each row is one simulated month. Grey RAND() columns draw demand condition, per-supplier disruption/severity, quality-yield variation and a common logistics shock from the Inputs sheet probabilities. Good supply per plant starts from the 'ILP_A_CostFocused' base allocation scaled by each supplier's capacity/yield draw. Before using the emergency market, any network shortfall is first partly covered by spare capacity at OTHER already-qualified suppliers (re-optimization among qualified sources, per the case's stated re-optimization rule) — then the 8,000-unit/month emergency market (Pune & Noida prioritized as high-criticality) — then any residue is unresolved shortage.
BZ3: Helper constants (do not delete) -> | CA3: AvgCost P1 | CB3: AvgCost P2 | CC3: AvgCost P3 | CD3: FreightBase
A4: LIVE SUMMARY (across all trial rows below) | CA4: =IFERROR(SUMPRODUCT(ILP_A_CostFocused!$C$9:$C$13,ILP_A_CostFocused!$B$36:$B$40)/SUM(ILP_A_CostFocused!$C$9:$C$13),0) -> 1031.005 | CB4: =IFERROR(SUMPRODUCT(ILP_A_CostFocused!$D$9:$D$13,ILP_A_CostFocused!$C$36:$C$40)/SUM(ILP_A_CostFocused!$D$9:$D$13),0) -> 1054.0417 | CC4: =IFERROR(SUMPRODUCT(ILP_A_CostFocused!$E$9:$E$13,ILP_A_CostFocused!$D$36:$D$40)/SUM(ILP_A_CostFocused!$E$9:$E$13),0) -> 1085.3059 | CD4: =(SUMPRODUCT(ILP_A_CostFocused!$C$9:$C$13,Inputs!$B$20:$B$24))+(SUMPRODUCT(ILP_A_CostFocused!$D$9:$D$13,Inputs!$C$20:$C$24))+(SUMPRODUCT(ILP_A_CostFocused!$E$9:$E$13,Inputs!$D$20:$D$24)) -> 2218180
A5: Network Shortage Prob. | B5: Expected Emergency Units | C5: Expected Unresolved Shortage | D5: Expected Emergency Cost | E5: Expected Shortage Cost | F5: Expected Sourcing Cost | G5: Expected Disruption Cost | H5: P1 Meets Demand | I5: P2 Meets Demand | J5: P3 Meets Demand
A6: =AVERAGE(BA8:BA157) -> 0 | B6: =AVERAGE(AU8:AU157) -> 16.090779 | C6: =AVERAGE(AR8:AR157)+AVERAGE(AT8:AT157)+AVERAGE(AS8:AS157) -> 0 | D6: =AVERAGE(AV8:AV157) -> 24940.707 | E6: =AVERAGE(AW8:AW157) -> 0 | F6: =AVERAGE(AX8:AX157)+AVERAGE(AY8:AY157) -> 44544932 | G6: =AVERAGE(AZ8:AZ157) -> 24940.707 | H6: =AVERAGE(BB8:BB157) -> 1 | I6: =AVERAGE(BC8:BC157) -> 1 | J6: =AVERAGE(BD8:BD157) -> 1
A7: Trial | B7: Rand Demand | C7: Demand Mult | D7: Rand Disrupt S1 | E7: Rand Disrupt S2 | F7: Rand Disrupt S3 | G7: Rand Disrupt S4 | H7: Rand Disrupt S5 | I7: Rand Shock | J7: Shock Mult | K7: Rand Severity S1 | L7: Rand Severity S2 | M7: Rand Severity S3 | N7: Rand Severity S4 | O7: Rand Severity S5 | P7: Rand Yield S1 | Q7: Rand Yield S2 | R7: Rand Yield S3 | S7: Rand Yield S4 | T7: Rand Yield S5 | U7: Eff.Factor S1 | V7: Eff.Factor S2 | W7: Eff.Factor S3 | X7: Eff.Factor S4 | Y7: Eff.Factor S5 | Z7: Good Supply P1 | AA7: Good Supply P2 | AB7: Good Supply P3 | AC7: Demand P1 | AD7: Demand P2 | AE7: Demand P3 | AF7: Shortfall P1 | AG7: Shortfall P2 | AH7: Shortfall P3 | AI7: Total Shortfall | AJ7: Spare Qual. Capacity Pool | AK7: Realloc. Used | AL7: Adj.Shortfall P1 | AM7: Adj.Shortfall P2 | AN7: Adj.Shortfall P3 | AO7: Emerg. P1 | AP7: Emerg. P3 | AQ7: Emerg. P2 | AR7: Unresolved P1 | AS7: Unresolved P3 | AT7: Unresolved P2 | AU7: Emergency Units | AV7: Emergency Cost ₹ | AW7: Shortage Cost ₹ | AX7: Sourcing Cost ₹ (approx) | AY7: Shock Cost ₹ | AZ7: Total Disrupt. Cost ₹ (Em+Short) | BA7: Unresolved Event? | BB7: P1 Met? | BC7: P2 Met? | BD7: P3 Met?
A8: 1 | B8: =RAND() -> 0.033471909 | C8: =IF(B8<=Inputs!$C$40,Inputs!$D$40,IF(B8<=Inputs!$C$41,Inputs!$D$41,Inputs!$D$42)) -> 0.9 | D8: =RAND() -> 0.97251302 | E8: =RAND() -> 0.98992691 | F8: =RAND() -> 0.83363548 | G8: =RAND() -> 0.013101136 | H8: =RAND() -> 0.017586614 | I8: =RAND() -> 0.44139556 | J8: =IF(I8<Inputs!$B$54,1+Inputs!$B$55,1) -> 1 | K8: =RAND() -> 0.12040297 | L8: =RAND() -> 0.46290402 | M8: =RAND() -> 0.87282378 | N8: =RAND() -> 0.24102502 | O8: =RAND() -> 0.45820368 | P8: =RAND() -> 0.50972151 | Q8: =RAND() -> 0.030927972 | R8: =RAND() -> 0.6409557 | ... T8: =RAND() -> 0.45597021 | U8: =(IF(D8>=Inputs!$E$12,1,IF(K8<=Inputs!$C$46,Inputs!$D$46,IF(K8<=Inputs!$C$47,Inputs!$D$47,Inputs!$D$48))))*((Inputs!$B$28+(P8-0.5)*2*Inputs!$B$53)/Inputs!$B$28) -> 1.0000984 | V8: =(IF(E8>=Inputs!$E$13,1,IF(L8<=Inputs!$C$46,Inputs!$D$46,IF(L8<=Inputs!$C$47,Inputs!$D$47,Inputs!$D$48))))*((Inputs!$B$29+(Q8-0.5)*2*Inputs!$B$53)/Inputs!$B$29) -> 0.99527145 | W8: =(IF(F8>=Inputs!$E$14,1,IF(M8<=Inputs!$C$46,Inputs!$D$46,IF(M8<=Inputs!$C$47,Inputs!$D$47,Inputs!$D$48))))*((Inputs!$B$30+(R8-0.5)*2*Inputs!$B$53)/Inputs!$B$30) -> 1.0014166 | X8: =(IF(G8>=Inputs!$E$15,1,IF(N8<=Inputs!$C$46,Inputs!$D$46,IF(N8<=Inputs!$C$47,Inputs!$D$47,Inputs!$D$48))))*((Inputs!$B$31+(S8-0.5)*2*Inputs!$B$53)/Inputs!$B$31) -> 0.60228662 | Y8: =(IF(H8>=Inputs!$E$16,1,IF(O8<=Inputs!$C$46,Inputs!$D$46,IF(O8<=Inputs!$C$47,Inputs!$D$47,Inputs!$D$48))))*((Inputs!$B$32+(T8-0.5)*2*Inputs!$B$53)/Inputs!$B$32) -> 0.29986711 | Z8: =ILP_A_CostFocused!$C$9*U8+ILP_A_CostFocused!$C$10*V8+ILP_A_CostFocused!$C$11*W8+ILP_A_CostFocused!$C$12*X8+ILP_A_CostFocused!$C$13*Y8 -> 13704.979 | AA8: =ILP_A_CostFocused!$D$9*U8+ILP_A_CostFocused!$D$10*V8+ILP_A_CostFocused!$D$11*W8+ILP_A_CostFocused!$D$12*X8+ILP_A_CostFocused!$D$13*Y8 -> 14558.83 | AB8: =ILP_A_CostFocused!$E$9*U8+ILP_A_CostFocused!$E$10*V8+ILP_A_CostFocused!$E$11*W8+ILP_A_CostFocused!$E$12*X8+ILP_A_CostFocused!$E$13*Y8 -> 11978.011 | AC8: =Inputs!$B$6*$C8 -> 16200 | AD8: =Inputs!$B$7*$C8 -> 13500 | AE8: =Inputs!$B$8*$C8 -> 10800 | AF8: =MAX(0,AC8-Z8) -> 2495.0208 | AG8: =MAX(0,AD8-AA8) -> 0 | AH8: =MAX(0,AE8-AB8) -> 0 | AI8: =SUM(AF8:AH8) -> 2495.0208 | AJ8: =U8*(Inputs!$B$12-ILP_A_CostFocused!$F$9)+V8*(Inputs!$B$13-ILP_A_CostFocused!$F$10)+W8*(Inputs!$B$14-ILP_A_CostFocused!$F$11)+X8*(Inputs!$B$15-ILP_A_CostFocused!$F$12)+Y8*(Inputs!$B$16-ILP_A_CostFocused!$F$13) -> 14437.416 | AK8: =MIN(AI8,MAX(0,AJ8)) -> 2495.0208 | AL8: =AF8*(1-(IF(AI8>0,AK8/AI8,0))) -> 0 | AM8: =AG8*(1-(IF(AI8>0,AK8/AI8,0))) -> 0 | AN8: =AH8*(1-(IF(AI8>0,AK8/AI8,0))) -> 0 | AO8: =MIN(AL8,Inputs!$B$36) -> 0 | AP8: =MIN(AN8,Inputs!$B$36-AO8) -> 0 | AQ8: =MIN(AM8,Inputs!$B$36-AO8-AP8) -> 0 | AR8: =AL8-AO8 -> 0 | AS8: =AN8-AP8 -> 0 | AT8: =AM8-AQ8 -> 0 | AU8: =AO8+AP8+AQ8 -> 0 | AV8: =AU8*Inputs!$B$35 -> 0 | AW8: =AR8*Inputs!$C$6+AT8*Inputs!$C$7+AS8*Inputs!$C$8 -> 0 | AX8: =Z8*$CA$4+AA8*$CB$4+AB8*$CC$4 -> 42475323 | AY8: =IF(J8>1,($CD$4)*Inputs!$B$55*((Z8+AA8+AB8)/(SUM(ILP_A_CostFocused!$C$9:$E$13))),0) -> 0 | AZ8: =AV8+AW8 -> 0 | BA8: =IF(AR8+AT8+AS8>0,1,0) -> 0 | BB8: =IF(AR8=0,1,0) -> 1 | BC8: =IF(AT8=0,1,0) -> 1 | BD8: =IF(AS8=0,1,0) -> 1
A9: 2 | B9: =RAND() -> 0.78390228 | C9: =IF(B9<=Inputs!$C$40,Inputs!$D$40,IF(B9<=Inputs!$C$41,Inputs!$D$41,Inputs!$D$42)) -> 1.15 | D9: =RAND() -> 0.96827388 | E9: =RAND() -> 0.052777357 | F9: =RAND() -> 0.78327809 | G9: =RAND() -> 0.53229921 | H9: =RAND() -> 0.466125 | I9: =RAND() -> 0.92790982 | J9: =IF(I9<Inputs!$B$54,1+Inputs!$B$55,1) -> 1 | K9: =RAND() -> 0.23274587 | L9: =RAND() -> 0.14188327 | M9: =RAND() -> 0.45752035 | N9: =RAND() -> 0.5600408 | O9: =RAND() -> 0.29113119 | P9: =RAND() -> 0.60822117 | Q9: =RAND() -> 0.8433939 | R9: =RAND() -> 0.58969811 | ... T9: =RAND() -> 0.71114679 | U9: =(IF(D9>=Inputs!$E$12,1,IF(K9<=Inputs!$C$46,Inputs!$D$46,IF(K9<=Inputs!$C$47,Inputs!$D$47,Inputs!$D$48))))*((Inputs!$B$28+(P9-0.5)*2*Inputs!$B$53)/Inputs!$B$28) -> 1.0010954 | V9: =(IF(E9>=Inputs!$E$13,1,IF(L9<=Inputs!$C$46,Inputs!$D$46,IF(L9<=Inputs!$C$47,Inputs!$D$47,Inputs!$D$48))))*((Inputs!$B$29+(Q9-0.5)*2*Inputs!$B$53)/Inputs!$B$29) -> 0.60207698 | W9: =(IF(F9>=Inputs!$E$14,1,IF(M9<=Inputs!$C$46,Inputs!$D$46,IF(M9<=Inputs!$C$47,Inputs!$D$47,Inputs!$D$48))))*((Inputs!$B$30+(R9-0.5)*2*Inputs!$B$53)/Inputs!$B$30) -> 1.0009015 | X9: =(IF(G9>=Inputs!$E$15,1,IF(N9<=Inputs!$C$46,Inputs!$D$46,IF(N9<=Inputs!$C$47,Inputs!$D$47,Inputs!$D$48))))*((Inputs!$B$31+(S9-0.5)*2*Inputs!$B$53)/Inputs!$B$31) -> 1.0044554 | Y9: =(IF(H9>=Inputs!$E$16,1,IF(O9<=Inputs!$C$46,Inputs!$D$46,IF(O9<=Inputs!$C$47,Inputs!$D$47,Inputs!$D$48))))*((Inputs!$B$32+(T9-0.5)*2*Inputs!$B$53)/Inputs!$B$32) -> 1.0021242 | Z9: =ILP_A_CostFocused!$C$9*U9+ILP_A_CostFocused!$C$10*V9+ILP_A_CostFocused!$C$11*W9+ILP_A_CostFocused!$C$12*X9+ILP_A_CostFocused!$C$13*Y9 -> 18020.892 | AA9: =ILP_A_CostFocused!$D$9*U9+ILP_A_CostFocused!$D$10*V9+ILP_A_CostFocused!$D$11*W9+ILP_A_CostFocused!$D$12*X9+ILP_A_CostFocused!$D$13*Y9 -> 11427.727 | AB9: =ILP_A_CostFocused!$E$9*U9+ILP_A_CostFocused!$E$10*V9+ILP_A_CostFocused!$E$11*W9+ILP_A_CostFocused!$E$12*X9+ILP_A_CostFocused!$E$13*Y9 -> 10097.856 | AC9: =Inputs!$B$6*$C9 -> 20700 | AD9: =Inputs!$B$7*$C9 -> 17250 | AE9: =Inputs!$B$8*$C9 -> 13800 | AF9: =MAX(0,AC9-Z9) -> 2679.1083 | AG9: =MAX(0,AD9-AA9) -> 5822.2732 | AH9: =MAX(0,AE9-AB9) -> 3702.1439 | AI9: =SUM(AF9:AH9) -> 12203.525 | AJ9: =U9*(Inputs!$B$12-ILP_A_CostFocused!$F$9)+V9*(Inputs!$B$13-ILP_A_CostFocused!$F$10)+W9*(Inputs!$B$14-ILP_A_CostFocused!$F$11)+X9*(Inputs!$B$15-ILP_A_CostFocused!$F$12)+Y9*(Inputs!$B$16-ILP_A_CostFocused!$F$13) -> 24997.177 | AK9: =MIN(AI9,MAX(0,AJ9)) -> 12203.525 | AL9: =AF9*(1-(IF(AI9>0,AK9/AI9,0))) -> 0 | AM9: =AG9*(1-(IF(AI9>0,AK9/AI9,0))) -> 0 | AN9: =AH9*(1-(IF(AI9>0,AK9/AI9,0))) -> 0 | AO9: =MIN(AL9,Inputs!$B$36) -> 0 | AP9: =MIN(AN9,Inputs!$B$36-AO9) -> 0 | AQ9: =MIN(AM9,Inputs!$B$36-AO9-AP9) -> 0 | AR9: =AL9-AO9 -> 0 | AS9: =AN9-AP9 -> 0 | AT9: =AM9-AQ9 -> 0 | AU9: =AO9+AP9+AQ9 -> 0 | AV9: =AU9*Inputs!$B$35 -> 0 | AW9: =AR9*Inputs!$C$6+AT9*Inputs!$C$7+AS9*Inputs!$C$8 -> 0 | AX9: =Z9*$CA$4+AA9*$CB$4+AB9*$CC$4 -> 41584193 | AY9: =IF(J9>1,($CD$4)*Inputs!$B$55*((Z9+AA9+AB9)/(SUM(ILP_A_CostFocused!$C$9:$E$13))),0) -> 0 | AZ9: =AV9+AW9 -> 0 | BA9: =IF(AR9+AT9+AS9>0,1,0) -> 0 | BB9: =IF(AR9=0,1,0) -> 1 | BC9: =IF(AT9=0,1,0) -> 1 | BD9: =IF(AS9=0,1,0) -> 1
A10: 3 | B10: =RAND() -> 0.6235639 | C10: =IF(B10<=Inputs!$C$40,Inputs!$D$40,IF(B10<=Inputs!$C$41,Inputs!$D$41,Inputs!$D$42)) -> 1 | D10: =RAND() -> 0.32923502 | E10: =RAND() -> 0.27812783 | F10: =RAND() -> 0.18646714 | G10: =RAND() -> 0.4308667 | H10: =RAND() -> 0.15908355 | I10: =RAND() -> 0.51645781 | J10: =IF(I10<Inputs!$B$54,1+Inputs!$B$55,1) -> 1 | K10: =RAND() -> 0.81353959 | L10: =RAND() -> 0.018189571 | M10: =RAND() -> 0.50446047 | N10: =RAND() -> 0.43064345 | O10: =RAND() -> 0.70983306 | P10: =RAND() -> 0.34817534 | Q10: =RAND() -> 0.95855357 | R10: =RAND() -> 0.90036398 | ... T10: =RAND() -> 0.80885371 | U10: =(IF(D10>=Inputs!$E$12,1,IF(K10<=Inputs!$C$46,Inputs!$D$46,IF(K10<=Inputs!$C$47,Inputs!$D$47,Inputs!$D$48))))*((Inputs!$B$28+(P10-0.5)*2*Inputs!$B$53)/Inputs!$B$28) -> 0.99846331 | V10: =(IF(E10>=Inputs!$E$13,1,IF(L10<=Inputs!$C$46,Inputs!$D$46,IF(L10<=Inputs!$C$47,Inputs!$D$47,Inputs!$D$48))))*((Inputs!$B$29+(Q10-0.5)*2*Inputs!$B$53)/Inputs!$B$29) -> 1.0046225 | W10: =(IF(F10>=Inputs!$E$14,1,IF(M10<=Inputs!$C$46,Inputs!$D$46,IF(M10<=Inputs!$C$47,Inputs!$D$47,Inputs!$D$48))))*((Inputs!$B$30+(R10-0.5)*2*Inputs!$B$53)/Inputs!$B$30) -> 1.0040238 | X10: =(IF(G10>=Inputs!$E$15,1,IF(N10<=Inputs!$C$46,Inputs!$D$46,IF(N10<=Inputs!$C$47,Inputs!$D$47,Inputs!$D$48))))*((Inputs!$B$31+(S10-0.5)*2*Inputs!$B$53)/Inputs!$B$31) -> 0.99694779 | Y10: =(IF(H10>=Inputs!$E$16,1,IF(O10<=Inputs!$C$46,Inputs!$D$46,IF(O10<=Inputs!$C$47,Inputs!$D$47,Inputs!$D$48))))*((Inputs!$B$32+(T10-0.5)*2*Inputs!$B$53)/Inputs!$B$32) -> 1.0031072 | Z10: =ILP_A_CostFocused!$C$9*U10+ILP_A_CostFocused!$C$10*V10+ILP_A_CostFocused!$C$11*W10+ILP_A_CostFocused!$C$12*X10+ILP_A_CostFocused!$C$13*Y10 -> 17956.514 | AA10: =ILP_A_CostFocused!$D$9*U10+ILP_A_CostFocused!$D$10*V10+ILP_A_CostFocused!$D$11*W10+ILP_A_CostFocused!$D$12*X10+ILP_A_CostFocused!$D$13*Y10 -> 15058.528 | AB10: =ILP_A_CostFocused!$E$9*U10+ILP_A_CostFocused!$E$10*V10+ILP_A_CostFocused!$E$11*W10+ILP_A_CostFocused!$E$12*X10+ILP_A_CostFocused!$E$13*Y10 -> 12011.124 | AC10: =Inputs!$B$6*$C10 -> 18000 | AD10: =Inputs!$B$7*$C10 -> 15000 | AE10: =Inputs!$B$8*$C10 -> 12000 | AF10: =MAX(0,AC10-Z10) -> 43.485992 | AG10: =MAX(0,AD10-AA10) -> 0 | AH10: =MAX(0,AE10-AB10) -> 0 | AI10: =SUM(AF10:AH10) -> 43.485992 | AJ10: =U10*(Inputs!$B$12-ILP_A_CostFocused!$F$9)+V10*(Inputs!$B$13-ILP_A_CostFocused!$F$10)+W10*(Inputs!$B$14-ILP_A_CostFocused!$F$11)+X10*(Inputs!$B$15-ILP_A_CostFocused!$F$12)+Y10*(Inputs!$B$16-ILP_A_CostFocused!$F$13) -> 25076.253 | AK10: =MIN(AI10,MAX(0,AJ10)) -> 43.485992 | AL10: =AF10*(1-(IF(AI10>0,AK10/AI10,0))) -> 0 | AM10: =AG10*(1-(IF(AI10>0,AK10/AI10,0))) -> 0 | AN10: =AH10*(1-(IF(AI10>0,AK10/AI10,0))) -> 0 | AO10: =MIN(AL10,Inputs!$B$36) -> 0 | AP10: =MIN(AN10,Inputs!$B$36-AO10) -> 0 | AQ10: =MIN(AM10,Inputs!$B$36-AO10-AP10) -> 0 | AR10: =AL10-AO10 -> 0 | AS10: =AN10-AP10 -> 0 | AT10: =AM10-AQ10 -> 0 | AU10: =AO10+AP10+AQ10 -> 0 | AV10: =AU10*Inputs!$B$35 -> 0 | AW10: =AR10*Inputs!$C$6+AT10*Inputs!$C$7+AS10*Inputs!$C$8 -> 0 | AX10: =Z10*$CA$4+AA10*$CB$4+AB10*$CC$4 -> 47421316 | AY10: =IF(J10>1,($CD$4)*Inputs!$B$55*((Z10+AA10+AB10)/(SUM(ILP_A_CostFocused!$C$9:$E$13))),0) -> 0 | AZ10: =AV10+AW10 -> 0 | BA10: =IF(AR10+AT10+AS10>0,1,0) -> 0 | BB10: =IF(AR10=0,1,0) -> 1 | BC10: =IF(AT10=0,1,0) -> 1 | BD10: =IF(AS10=0,1,0) -> 1
A11: 4 | B11: =RAND() -> 0.56238363 | C11: =IF(B11<=Inputs!$C$40,Inputs!$D$40,IF(B11<=Inputs!$C$41,Inputs!$D$41,Inputs!$D$42)) -> 1 | D11: =RAND() -> 0.60154579 | E11: =RAND() -> 0.17586783 | F11: =RAND() -> 0.64473738 | G11: =RAND() -> 0.39659774 | H11: =RAND() -> 0.5205288 | I11: =RAND() -> 0.27858428 | J11: =IF(I11<Inputs!$B$54,1+Inputs!$B$55,1) -> 1 | K11: =RAND() -> 0.98043147 | L11: =RAND() -> 0.21829612 | M11: =RAND() -> 0.46208726 | N11: =RAND() -> 0.40819892 | O11: =RAND() -> 0.082775084 | P11: =RAND() -> 0.34771854 | Q11: =RAND() -> 0.6069424 | R11: =RAND() -> 0.62274386 | ... T11: =RAND() -> 0.93154719 | U11: =(IF(D11>=Inputs!$E$12,1,IF(K11<=Inputs!$C$46,Inputs!$D$46,IF(K11<=Inputs!$C$47,Inputs!$D$47,Inputs!$D$48))))*((Inputs!$B$28+(P11-0.5)*2*Inputs!$B$53)/Inputs!$B$28) -> 0.99845869 | V11: =(IF(E11>=Inputs!$E$13,1,IF(L11<=Inputs!$C$46,Inputs!$D$46,IF(L11<=Inputs!$C$47,Inputs!$D$47,Inputs!$D$48))))*((Inputs!$B$29+(Q11-0.5)*2*Inputs!$B$53)/Inputs!$B$29) -> 1.001078 | W11: =(IF(F11>=Inputs!$E$14,1,IF(M11<=Inputs!$C$46,Inputs!$D$46,IF(M11<=Inputs!$C$47,Inputs!$D$47,Inputs!$D$48))))*((Inputs!$B$30+(R11-0.5)*2*Inputs!$B$53)/Inputs!$B$30) -> 1.0012336 | X11: =(IF(G11>=Inputs!$E$15,1,IF(N11<=Inputs!$C$46,Inputs!$D$46,IF(N11<=Inputs!$C$47,Inputs!$D$47,Inputs!$D$48))))*((Inputs!$B$31+(S11-0.5)*2*Inputs!$B$53)/Inputs!$B$31) -> 1.0023338 | Y11: =(IF(H11>=Inputs!$E$16,1,IF(O11<=Inputs!$C$46,Inputs!$D$46,IF(O11<=Inputs!$C$47,Inputs!$D$47,Inputs!$D$48))))*((Inputs!$B$32+(T11-0.5)*2*Inputs!$B$53)/Inputs!$B$32) -> 1.0043415 | Z11: =ILP_A_CostFocused!$C$9*U11+ILP_A_CostFocused!$C$10*V11+ILP_A_CostFocused!$C$11*W11+ILP_A_CostFocused!$C$12*X11+ILP_A_CostFocused!$C$13*Y11 -> 18014.338 | AA11: =ILP_A_CostFocused!$D$9*U11+ILP_A_CostFocused!$D$10*V11+ILP_A_CostFocused!$D$11*W11+ILP_A_CostFocused!$D$12*X11+ILP_A_CostFocused!$D$13*Y11 -> 15018.226 | AB11: =ILP_A_CostFocused!$E$9*U11+ILP_A_CostFocused!$E$10*V11+ILP_A_CostFocused!$E$11*W11+ILP_A_CostFocused!$E$12*X11+ILP_A_CostFocused!$E$13*Y11 -> 11994.077 | AC11: =Inputs!$B$6*$C11 -> 18000 | AD11: =Inputs!$B$7*$C11 -> 15000 | AE11: =Inputs!$B$8*$C11 -> 12000 | AF11: =MAX(0,AC11-Z11) -> 0 | AG11: =MAX(0,AD11-AA11) -> 0 | AH11: =MAX(0,AE11-AB11) -> 5.9228021 | AI11: =SUM(AF11:AH11) -> 5.9228021 | AJ11: =U11*(Inputs!$B$12-ILP_A_CostFocused!$F$9)+V11*(Inputs!$B$13-ILP_A_CostFocused!$F$10)+W11*(Inputs!$B$14-ILP_A_CostFocused!$F$11)+X11*(Inputs!$B$15-ILP_A_CostFocused!$F$12)+Y11*(Inputs!$B$16-ILP_A_CostFocused!$F$13) -> 25072.955 | AK11: =MIN(AI11,MAX(0,AJ11)) -> 5.9228021 | AL11: =AF11*(1-(IF(AI11>0,AK11/AI11,0))) -> 0 | AM11: =AG11*(1-(IF(AI11>0,AK11/AI11,0))) -> 0 | AN11: =AH11*(1-(IF(AI11>0,AK11/AI11,0))) -> 0 | AO11: =MIN(AL11,Inputs!$B$36) -> 0 | AP11: =MIN(AN11,Inputs!$B$36-AO11) -> 0 | AQ11: =MIN(AM11,Inputs!$B$36-AO11-AP11) -> 0 | AR11: =AL11-AO11 -> 0 | AS11: =AN11-AP11 -> 0 | AT11: =AM11-AQ11 -> 0 | AU11: =AO11+AP11+AQ11 -> 0 | AV11: =AU11*Inputs!$B$35 -> 0 | AW11: =AR11*Inputs!$C$6+AT11*Inputs!$C$7+AS11*Inputs!$C$8 -> 0 | AX11: =Z11*$CA$4+AA11*$CB$4+AB11*$CC$4 -> 47419953 | AY11: =IF(J11>1,($CD$4)*Inputs!$B$55*((Z11+AA11+AB11)/(SUM(ILP_A_CostFocused!$C$9:$E$13))),0) -> 0 | AZ11: =AV11+AW11 -> 0 | BA11: =IF(AR11+AT11+AS11>0,1,0) -> 0 | BB11: =IF(AR11=0,1,0) -> 1 | BC11: =IF(AT11=0,1,0) -> 1 | BD11: =IF(AS11=0,1,0) -> 1
A12: 5 | B12: =RAND() -> 0.27306211 | C12: =IF(B12<=Inputs!$C$40,Inputs!$D$40,IF(B12<=Inputs!$C$41,Inputs!$D$41,Inputs!$D$42)) -> 1 | D12: =RAND() -> 0.13836154 | E12: =RAND() -> 0.35367837 | F12: =RAND() -> 0.58666541 | G12: =RAND() -> 0.80685571 | H12: =RAND() -> 0.47863623 | I12: =RAND() -> 0.62261025 | J12: =IF(I12<Inputs!$B$54,1+Inputs!$B$55,1) -> 1 | K12: =RAND() -> 0.09518567 | L12: =RAND() -> 0.88906643 | M12: =RAND() -> 0.30585567 | N12: =RAND() -> 0.28736546 | O12: =RAND() -> 0.5156544 | P12: =RAND() -> 0.026020906 | Q12: =RAND() -> 0.77502534 | R12: =RAND() -> 0.041909221 | ... T12: =RAND() -> 0.095191414 | U12: =(IF(D12>=Inputs!$E$12,1,IF(K12<=Inputs!$C$46,Inputs!$D$46,IF(K12<=Inputs!$C$47,Inputs!$D$47,Inputs!$D$48))))*((Inputs!$B$28+(P12-0.5)*2*Inputs!$B$53)/Inputs!$B$28) -> 0.99520264 | V12: =(IF(E12>=Inputs!$E$13,1,IF(L12<=Inputs!$C$46,Inputs!$D$46,IF(L12<=Inputs!$C$47,Inputs!$D$47,Inputs!$D$48))))*((Inputs!$B$29+(Q12-0.5)*2*Inputs!$B$53)/Inputs!$B$29) -> 1.0027724 | W12: =(IF(F12>=Inputs!$E$14,1,IF(M12<=Inputs!$C$46,Inputs!$D$46,IF(M12<=Inputs!$C$47,Inputs!$D$47,Inputs!$D$48))))*((Inputs!$B$30+(R12-0.5)*2*Inputs!$B$53)/Inputs!$B$30) -> 0.99539607 | X12: =(IF(G12>=Inputs!$E$15,1,IF(N12<=Inputs!$C$46,Inputs!$D$46,IF(N12<=Inputs!$C$47,Inputs!$D$47,Inputs!$D$48))))*((Inputs!$B$31+(S12-0.5)*2*Inputs!$B$53)/Inputs!$B$31) -> 1.0015207 | Y12: =(IF(H12>=Inputs!$E$16,1,IF(O12<=Inputs!$C$46,Inputs!$D$46,IF(O12<=Inputs!$C$47,Inputs!$D$47,Inputs!$D$48))))*((Inputs!$B$32+(T12-0.5)*2*Inputs!$B$53)/Inputs!$B$32) -> 0.99592748 | Z12: =ILP_A_CostFocused!$C$9*U12+ILP_A_CostFocused!$C$10*V12+ILP_A_CostFocused!$C$11*W12+ILP_A_CostFocused!$C$12*X12+ILP_A_CostFocused!$C$13*Y12 -> 17982.548 | AA12: =ILP_A_CostFocused!$D$9*U12+ILP_A_CostFocused!$D$10*V12+ILP_A_CostFocused!$D$11*W12+ILP_A_CostFocused!$D$12*X12+ILP_A_CostFocused!$D$13*Y12 -> 15003.575 | AB12: =ILP_A_CostFocused!$E$9*U12+ILP_A_CostFocused!$E$10*V12+ILP_A_CostFocused!$E$11*W12+ILP_A_CostFocused!$E$12*X12+ILP_A_CostFocused!$E$13*Y12 -> 11978.767 | AC12: =Inputs!$B$6*$C12 -> 18000 | AD12: =Inputs!$B$7*$C12 -> 15000 | AE12: =Inputs!$B$8*$C12 -> 12000 | AF12: =MAX(0,AC12-Z12) -> 17.451503 | AG12: =MAX(0,AD12-AA12) -> 0 | AH12: =MAX(0,AE12-AB12) -> 21.233309 | AI12: =SUM(AF12:AH12) -> 38.684812 | AJ12: =U12*(Inputs!$B$12-ILP_A_CostFocused!$F$9)+V12*(Inputs!$B$13-ILP_A_CostFocused!$F$10)+W12*(Inputs!$B$14-ILP_A_CostFocused!$F$11)+X12*(Inputs!$B$15-ILP_A_CostFocused!$F$12)+Y12*(Inputs!$B$16-ILP_A_CostFocused!$F$13) -> 24894.475 | AK12: =MIN(AI12,MAX(0,AJ12)) -> 38.684812 | AL12: =AF12*(1-(IF(AI12>0,AK12/AI12,0))) -> 0 | AM12: =AG12*(1-(IF(AI12>0,AK12/AI12,0))) -> 0 | AN12: =AH12*(1-(IF(AI12>0,AK12/AI12,0))) -> 0 | AO12: =MIN(AL12,Inputs!$B$36) -> 0 | AP12: =MIN(AN12,Inputs!$B$36-AO12) -> 0 | AQ12: =MIN(AM12,Inputs!$B$36-AO12-AP12) -> 0 | AR12: =AL12-AO12 -> 0 | AS12: =AN12-AP12 -> 0 | AT12: =AM12-AQ12 -> 0 | AU12: =AO12+AP12+AQ12 -> 0 | AV12: =AU12*Inputs!$B$35 -> 0 | AW12: =AR12*Inputs!$C$6+AT12*Inputs!$C$7+AS12*Inputs!$C$8 -> 0 | AX12: =Z12*$CA$4+AA12*$CB$4+AB12*$CC$4 -> 47355118 | AY12: =IF(J12>1,($CD$4)*Inputs!$B$55*((Z12+AA12+AB12)/(SUM(ILP_A_CostFocused!$C$9:$E$13))),0) -> 0 | AZ12: =AV12+AW12 -> 0 | BA12: =IF(AR12+AT12+AS12>0,1,0) -> 0 | BB12: =IF(AR12=0,1,0) -> 1 | BC12: =IF(AT12=0,1,0) -> 1 | BD12: =IF(AS12=0,1,0) -> 1
A13: 6 | B13: =RAND() -> 0.74459154 | C13: =IF(B13<=Inputs!$C$40,Inputs!$D$40,IF(B13<=Inputs!$C$41,Inputs!$D$41,Inputs!$D$42)) -> 1 | D13: =RAND() -> 0.12032964 | E13: =RAND() -> 0.69191537 | F13: =RAND() -> 0.58243387 | G13: =RAND() -> 0.65957125 | H13: =RAND() -> 0.70495966 | I13: =RAND() -> 0.025456823 | J13: =IF(I13<Inputs!$B$54,1+Inputs!$B$55,1) -> 1.25 | K13: =RAND() -> 0.83648196 | L13: =RAND() -> 0.49016139 | M13: =RAND() -> 0.3709532 | N13: =RAND() -> 0.53191723 | O13: =RAND() -> 0.51911195 | P13: =RAND() -> 0.057955424 | Q13: =RAND() -> 0.96480061 | R13: =RAND() -> 0.64230895 | ... T13: =RAND() -> 0.24566329 | U13: =(IF(D13>=Inputs!$E$12,1,IF(K13<=Inputs!$C$46,Inputs!$D$46,IF(K13<=Inputs!$C$47,Inputs!$D$47,Inputs!$D$48))))*((Inputs!$B$28+(P13-0.5)*2*Inputs!$B$53)/Inputs!$B$28) -> 0.99552586 | V13: =(IF(E13>=Inputs!$E$13,1,IF(L13<=Inputs!$C$46,Inputs!$D$46,IF(L13<=Inputs!$C$47,Inputs!$D$47,Inputs!$D$48))))*((Inputs!$B$29+(Q13-0.5)*2*Inputs!$B$53)/Inputs!$B$29) -> 1.0046855 | W13: =(IF(F13>=Inputs!$E$14,1,IF(M13<=Inputs!$C$46,Inputs!$D$46,IF(M13<=Inputs!$C$47,Inputs!$D$47,Inputs!$D$48))))*((Inputs!$B$30+(R13-0.5)*2*Inputs!$B$53)/Inputs!$B$30) -> 1.0014302 | X13: =(IF(G13>=Inputs!$E$15,1,IF(N13<=Inputs!$C$46,Inputs!$D$46,IF(N13<=Inputs!$C$47,Inputs!$D$47,Inputs!$D$48))))*((Inputs!$B$31+(S13-0.5)*2*Inputs!$B$53)/Inputs!$B$31) -> 1.0024115 | Y13: =(IF(H13>=Inputs!$E$16,1,IF(O13<=Inputs!$C$46,Inputs!$D$46,IF(O13<=Inputs!$C$47,Inputs!$D$47,Inputs!$D$48))))*((Inputs!$B$32+(T13-0.5)*2*Inputs!$B$53)/Inputs!$B$32) -> 0.99744128 | Z13: =ILP_A_CostFocused!$C$9*U13+ILP_A_CostFocused!$C$10*V13+ILP_A_CostFocused!$C$11*W13+ILP_A_CostFocused!$C$12*X13+ILP_A_CostFocused!$C$13*Y13 -> 17994.636 | AA13: =ILP_A_CostFocused!$D$9*U13+ILP_A_CostFocused!$D$10*V13+ILP_A_CostFocused!$D$11*W13+ILP_A_CostFocused!$D$12*X13+ILP_A_CostFocused!$D$13*Y13 -> 15051.752 | AB13: =ILP_A_CostFocused!$E$9*U13+ILP_A_CostFocused!$E$10*V13+ILP_A_CostFocused!$E$11*W13+ILP_A_CostFocused!$E$12*X13+ILP_A_CostFocused!$E$13*Y13 -> 11990.277 | AC13: =Inputs!$B$6*$C13 -> 18000 | AD13: =Inputs!$B$7*$C13 -> 15000 | AE13: =Inputs!$B$8*$C13 -> 12000 | AF13: =MAX(0,AC13-Z13) -> 5.363792 | AG13: =MAX(0,AD13-AA13) -> 0 | AH13: =MAX(0,AE13-AB13) -> 9.7234225 | AI13: =SUM(AF13:AH13) -> 15.087215 | AJ13: =U13*(Inputs!$B$12-ILP_A_CostFocused!$F$9)+V13*(Inputs!$B$13-ILP_A_CostFocused!$F$10)+W13*(Inputs!$B$14-ILP_A_CostFocused!$F$11)+X13*(Inputs!$B$15-ILP_A_CostFocused!$F$12)+Y13*(Inputs!$B$16-ILP_A_CostFocused!$F$13) -> 24966.496 | AK13: =MIN(AI13,MAX(0,AJ13)) -> 15.087215 | AL13: =AF13*(1-(IF(AI13>0,AK13/AI13,0))) -> 0 | AM13: =AG13*(1-(IF(AI13>0,AK13/AI13,0))) -> 0 | AN13: =AH13*(1-(IF(AI13>0,AK13/AI13,0))) -> 0 | AO13: =MIN(AL13,Inputs!$B$36) -> 0 | AP13: =MIN(AN13,Inputs!$B$36-AO13) -> 0 | AQ13: =MIN(AM13,Inputs!$B$36-AO13-AP13) -> 0 | AR13: =AL13-AO13 -> 0 | AS13: =AN13-AP13 -> 0 | AT13: =AM13-AQ13 -> 0 | AU13: =AO13+AP13+AQ13 -> 0 | AV13: =AU13*Inputs!$B$35 -> 0 | AW13: =AR13*Inputs!$C$6+AT13*Inputs!$C$7+AS13*Inputs!$C$8 -> 0 | AX13: =Z13*$CA$4+AA13*$CB$4+AB13*$CC$4 -> 47430852 | AY13: =IF(J13>1,($CD$4)*Inputs!$B$55*((Z13+AA13+AB13)/(SUM(ILP_A_CostFocused!$C$9:$E$13))),0) -> 554996.82 | AZ13: =AV13+AW13 -> 0 | BA13: =IF(AR13+AT13+AS13>0,1,0) -> 0 | BB13: =IF(AR13=0,1,0) -> 1 | BC13: =IF(AT13=0,1,0) -> 1 | BD13: =IF(AS13=0,1,0) -> 1
A14: 7 | B14: =RAND() -> 0.98037986 | C14: =IF(B14<=Inputs!$C$40,Inputs!$D$40,IF(B14<=Inputs!$C$41,Inputs!$D$41,Inputs!$D$42)) -> 1.15 | D14: =RAND() -> 0.66728003 | E14: =RAND() -> 0.68654331 | F14: =RAND() -> 0.064286941 | G14: =RAND() -> 0.21441576 | H14: =RAND() -> 0.93161277 | I14: =RAND() -> 0.53613749 | J14: =IF(I14<Inputs!$B$54,1+Inputs!$B$55,1) -> 1 | K14: =RAND() -> 0.77283897 | L14: =RAND() -> 0.069422386 | M14: =RAND() -> 0.0041772366 | N14: =RAND() -> 0.47701311 | O14: =RAND() -> 0.48017779 | P14: =RAND() -> 0.081335725 | Q14: =RAND() -> 0.72664781 | R14: =RAND() -> 0.81522732 | ... T14: =RAND() -> 0.33052909 | U14: =(IF(D14>=Inputs!$E$12,1,IF(K14<=Inputs!$C$46,Inputs!$D$46,IF(K14<=Inputs!$C$47,Inputs!$D$47,Inputs!$D$48))))*((Inputs!$B$28+(P14-0.5)*2*Inputs!$B$53)/Inputs!$B$28) -> 0.99576251 | V14: =(IF(E14>=Inputs!$E$13,1,IF(L14<=Inputs!$C$46,Inputs!$D$46,IF(L14<=Inputs!$C$47,Inputs!$D$47,Inputs!$D$48))))*((Inputs!$B$29+(Q14-0.5)*2*Inputs!$B$53)/Inputs!$B$29) -> 1.0022848 | W14: =(IF(F14>=Inputs!$E$14,1,IF(M14<=Inputs!$C$46,Inputs!$D$46,IF(M14<=Inputs!$C$47,Inputs!$D$47,Inputs!$D$48))))*((Inputs!$B$30+(R14-0.5)*2*Inputs!$B$53)/Inputs!$B$30) -> 1.0031681 | X14: =(IF(G14>=Inputs!$E$15,1,IF(N14<=Inputs!$C$46,Inputs!$D$46,IF(N14<=Inputs!$C$47,Inputs!$D$47,Inputs!$D$48))))*((Inputs!$B$31+(S14-0.5)*2*Inputs!$B$53)/Inputs!$B$31) -> 1.0007949 | Y14: =(IF(H14>=Inputs!$E$16,1,IF(O14<=Inputs!$C$46,Inputs!$D$46,IF(O14<=Inputs!$C$47,Inputs!$D$47,Inputs!$D$48))))*((Inputs!$B$32+(T14-0.5)*2*Inputs!$B$53)/Inputs!$B$32) -> 0.99829506 | Z14: =ILP_A_CostFocused!$C$9*U14+ILP_A_CostFocused!$C$10*V14+ILP_A_CostFocused!$C$11*W14+ILP_A_CostFocused!$C$12*X14+ILP_A_CostFocused!$C$13*Y14 -> 17978.649 | AA14: =ILP_A_CostFocused!$D$9*U14+ILP_A_CostFocused!$D$10*V14+ILP_A_CostFocused!$D$11*W14+ILP_A_CostFocused!$D$12*X14+ILP_A_CostFocused!$D$13*Y14 -> 15037.151 | AB14: =ILP_A_CostFocused!$E$9*U14+ILP_A_CostFocused!$E$10*V14+ILP_A_CostFocused!$E$11*W14+ILP_A_CostFocused!$E$12*X14+ILP_A_CostFocused!$E$13*Y14 -> 11980.457 | AC14: =Inputs!$B$6*$C14 -> 20700 | AD14: =Inputs!$B$7*$C14 -> 17250 | AE14: =Inputs!$B$8*$C14 -> 13800 | AF14: =MAX(0,AC14-Z14) -> 2721.3513 | AG14: =MAX(0,AD14-AA14) -> 2212.8492 | AH14: =MAX(0,AE14-AB14) -> 1819.5431 | AI14: =SUM(AF14:AH14) -> 6753.7436 | AJ14: =U14*(Inputs!$B$12-ILP_A_CostFocused!$F$9)+V14*(Inputs!$B$13-ILP_A_CostFocused!$F$10)+W14*(Inputs!$B$14-ILP_A_CostFocused!$F$11)+X14*(Inputs!$B$15-ILP_A_CostFocused!$F$12)+Y14*(Inputs!$B$16-ILP_A_CostFocused!$F$13) -> 24993.08 | AK14: =MIN(AI14,MAX(0,AJ14)) -> 6753.7436 | AL14: =AF14*(1-(IF(AI14>0,AK14/AI14,0))) -> 0 | AM14: =AG14*(1-(IF(AI14>0,AK14/AI14,0))) -> 0 | AN14: =AH14*(1-(IF(AI14>0,AK14/AI14,0))) -> 0 | AO14: =MIN(AL14,Inputs!$B$36) -> 0 | AP14: =MIN(AN14,Inputs!$B$36-AO14) -> 0 | AQ14: =MIN(AM14,Inputs!$B$36-AO14-AP14) -> 0 | AR14: =AL14-AO14 -> 0 | AS14: =AN14-AP14 -> 0 | AT14: =AM14-AQ14 -> 0 | AU14: =AO14+AP14+AQ14 -> 0 | AV14: =AU14*Inputs!$B$35 -> 0 | AW14: =AR14*Inputs!$C$6+AT14*Inputs!$C$7+AS14*Inputs!$C$8 -> 0 | AX14: =Z14*$CA$4+AA14*$CB$4+AB14*$CC$4 -> 47388322 | AY14: =IF(J14>1,($CD$4)*Inputs!$B$55*((Z14+AA14+AB14)/(SUM(ILP_A_CostFocused!$C$9:$E$13))),0) -> 0 | AZ14: =AV14+AW14 -> 0 | BA14: =IF(AR14+AT14+AS14>0,1,0) -> 0 | BB14: =IF(AR14=0,1,0) -> 1 | BC14: =IF(AT14=0,1,0) -> 1 | BD14: =IF(AS14=0,1,0) -> 1
A15: 8 | B15: =RAND() -> 0.40245805 | C15: =IF(B15<=Inputs!$C$40,Inputs!$D$40,IF(B15<=Inputs!$C$41,Inputs!$D$41,Inputs!$D$42)) -> 1 | D15: =RAND() -> 0.92708308 | E15: =RAND() -> 0.047589422 | F15: =RAND() -> 0.50885059 | G15: =RAND() -> 0.27976017 | H15: =RAND() -> 0.61941938 | I15: =RAND() -> 0.20796391 | J15: =IF(I15<Inputs!$B$54,1+Inputs!$B$55,1) -> 1 | K15: =RAND() -> 0.92699659 | L15: =RAND() -> 0.20687416 | M15: =RAND() -> 0.31873274 | N15: =RAND() -> 0.40943198 | O15: =RAND() -> 0.41693488 | P15: =RAND() -> 0.80103348 | Q15: =RAND() -> 0.18468137 | R15: =RAND() -> 0.21864338 | ... T15: =RAND() -> 0.22367099 | U15: =(IF(D15>=Inputs!$E$12,1,IF(K15<=Inputs!$C$46,Inputs!$D$46,IF(K15<=Inputs!$C$47,Inputs!$D$47,Inputs!$D$48))))*((Inputs!$B$28+(P15-0.5)*2*Inputs!$B$53)/Inputs!$B$28) -> 1.0030469 | V15: =(IF(E15>=Inputs!$E$13,1,IF(L15<=Inputs!$C$46,Inputs!$D$46,IF(L15<=Inputs!$C$47,Inputs!$D$47,Inputs!$D$48))))*((Inputs!$B$29+(Q15-0.5)*2*Inputs!$B$53)/Inputs!$B$29) -> 0.59809283 | W15: =(IF(F15>=Inputs!$E$14,1,IF(M15<=Inputs!$C$46,Inputs!$D$46,IF(M15<=Inputs!$C$47,Inputs!$D$47,Inputs!$D$48))))*((Inputs!$B$30+(R15-0.5)*2*Inputs!$B$53)/Inputs!$B$30) -> 0.9971723 | X15: =(IF(G15>=Inputs!$E$15,1,IF(N15<=Inputs!$C$46,Inputs!$D$46,IF(N15<=Inputs!$C$47,Inputs!$D$47,Inputs!$D$48))))*((Inputs!$B$31+(S15-0.5)*2*Inputs!$B$53)/Inputs!$B$31) -> 0.99784897 | Y15: =(IF(H15>=Inputs!$E$16,1,IF(O15<=Inputs!$C$46,Inputs!$D$46,IF(O15<=Inputs!$C$47,Inputs!$D$47,Inputs!$D$48))))*((Inputs!$B$32+(T15-0.5)*2*Inputs!$B$53)/Inputs!$B$32) -> 0.99722003 | Z15: =ILP_A_CostFocused!$C$9*U15+ILP_A_CostFocused!$C$10*V15+ILP_A_CostFocused!$C$11*W15+ILP_A_CostFocused!$C$12*X15+ILP_A_CostFocused!$C$13*Y15 -> 17963.071 | AA15: =ILP_A_CostFocused!$D$9*U15+ILP_A_CostFocused!$D$10*V15+ILP_A_CostFocused!$D$11*W15+ILP_A_CostFocused!$D$12*X15+ILP_A_CostFocused!$D$13*Y15 -> 11366.559 | AB15: =ILP_A_CostFocused!$E$9*U15+ILP_A_CostFocused!$E$10*V15+ILP_A_CostFocused!$E$11*W15+ILP_A_CostFocused!$E$12*X15+ILP_A_CostFocused!$E$13*Y15 -> 10092.783 | AC15: =Inputs!$B$6*$C15 -> 18000 | AD15: =Inputs!$B$7*$C15 -> 15000 | AE15: =Inputs!$B$8*$C15 -> 12000 | AF15: =MAX(0,AC15-Z15) -> 36.929425 | AG15: =MAX(0,AD15-AA15) -> 3633.4405 | AH15: =MAX(0,AE15-AB15) -> 1907.2167 | AI15: =SUM(AF15:AH15) -> 5577.5867 | AJ15: =U15*(Inputs!$B$12-ILP_A_CostFocused!$F$9)+V15*(Inputs!$B$13-ILP_A_CostFocused!$F$10)+W15*(Inputs!$B$14-ILP_A_CostFocused!$F$11)+X15*(Inputs!$B$15-ILP_A_CostFocused!$F$12)+Y15*(Inputs!$B$16-ILP_A_CostFocused!$F$13) -> 24895.365 | AK15: =MIN(AI15,MAX(0,AJ15)) -> 5577.5867 | AL15: =AF15*(1-(IF(AI15>0,AK15/AI15,0))) -> 0 | AM15: =AG15*(1-(IF(AI15>0,AK15/AI15,0))) -> 0 | AN15: =AH15*(1-(IF(AI15>0,AK15/AI15,0))) -> 0 | AO15: =MIN(AL15,Inputs!$B$36) -> 0 | AP15: =MIN(AN15,Inputs!$B$36-AO15) -> 0 | AQ15: =MIN(AM15,Inputs!$B$36-AO15-AP15) -> 0 | AR15: =AL15-AO15 -> 0 | AS15: =AN15-AP15 -> 0 | AT15: =AM15-AQ15 -> 0 | AU15: =AO15+AP15+AQ15 -> 0 | AV15: =AU15*Inputs!$B$35 -> 0 | AW15: =AR15*Inputs!$C$6+AT15*Inputs!$C$7+AS15*Inputs!$C$8 -> 0 | AX15: =Z15*$CA$4+AA15*$CB$4+AB15*$CC$4 -> 41454601 | AY15: =IF(J15>1,($CD$4)*Inputs!$B$55*((Z15+AA15+AB15)/(SUM(ILP_A_CostFocused!$C$9:$E$13))),0) -> 0 | AZ15: =AV15+AW15 -> 0 | BA15: =IF(AR15+AT15+AS15>0,1,0) -> 0 | BB15: =IF(AR15=0,1,0) -> 1 | BC15: =IF(AT15=0,1,0) -> 1 | BD15: =IF(AS15=0,1,0) -> 1
